Workbook

Sheet สรุป
A1: รายการ Asset ที่ต้องทำ — Board Games
A2: แต่ละแท็บคือ 1 เกม แก้คอลัมน์ 'สถานะ' ได้จาก dropdown แล้วตารางนี้จะนับให้เอง ทุกแถวมีภาพที่วาดด้วยโค้ดอยู่แล้ว จึงทยอยทำทีละชิ้นได้
A4: แท็บ | B4: จำนวนแถว | C4: ความสำคัญสูง | D4: เสร็จแล้ว | E4: กำลังทำ | F4: ยังไม่เริ่ม | G4: ความคืบหน้า
A5: ทั่วไป | B5: =COUNTA('ทั่วไป'!A:A)-1 | C5: =COUNTIF('ทั่วไป'!J:J,"สูง") | D5: =COUNTIF('ทั่วไป'!M:M,"เสร็จแล้ว") | E5: =COUNTIF('ทั่วไป'!M:M,"กำลังทำ") | F5: =COUNTIF('ทั่วไป'!M:M,"ยังไม่เริ่ม") | G5: =IF(B5-COUNTIF('ทั่วไป'!M:M,"ไม่ทำ")=0,0,D5/(B5-COUNTIF('ทั่วไป'!M:M,"ไม่ทำ")))
A6: กองไฟ (Werewolf+ONW) | B6: =COUNTA('กองไฟ (Werewolf+ONW)'!A:A)-1 | C6: =COUNTIF('กองไฟ (Werewolf+ONW)'!J:J,"สูง") | D6: =COUNTIF('กองไฟ (Werewolf+ONW)'!M:M,"เสร็จแล้ว") | E6: =COUNTIF('กองไฟ (Werewolf+ONW)'!M:M,"กำลังทำ") | F6: =COUNTIF('กองไฟ (Werewolf+ONW)'!M:M,"ยังไม่เริ่ม") | G6: =IF(B6-COUNTIF('กองไฟ (Werewolf+ONW)'!M:M,"ไม่ทำ")=0,0,D6/(B6-COUNTIF('กองไฟ (Werewolf+ONW)'!M:M,"ไม่ทำ")))
A7: Werewolf | B7: =COUNTA('Werewolf'!A:A)-1 | C7: =COUNTIF('Werewolf'!J:J,"สูง") | D7: =COUNTIF('Werewolf'!M:M,"เสร็จแล้ว") | E7: =COUNTIF('Werewolf'!M:M,"กำลังทำ") | F7: =COUNTIF('Werewolf'!M:M,"ยังไม่เริ่ม") | G7: =IF(B7-COUNTIF('Werewolf'!M:M,"ไม่ทำ")=0,0,D7/(B7-COUNTIF('Werewolf'!M:M,"ไม่ทำ")))
A8: One Night | B8: =COUNTA('One Night'!A:A)-1 | C8: =COUNTIF('One Night'!J:J,"สูง") | D8: =COUNTIF('One Night'!M:M,"เสร็จแล้ว") | E8: =COUNTIF('One Night'!M:M,"กำลังทำ") | F8: =COUNTIF('One Night'!M:M,"ยังไม่เริ่ม") | G8: =IF(B8-COUNTIF('One Night'!M:M,"ไม่ทำ")=0,0,D8/(B8-COUNTIF('One Night'!M:M,"ไม่ทำ")))
A9: Feed the Kraken | B9: =COUNTA('Feed the Kraken'!A:A)-1 | C9: =COUNTIF('Feed the Kraken'!J:J,"สูง") | D9: =COUNTIF('Feed the Kraken'!M:M,"เสร็จแล้ว") | E9: =COUNTIF('Feed the Kraken'!M:M,"กำลังทำ") | F9: =COUNTIF('Feed the Kraken'!M:M,"ยังไม่เริ่ม") | G9: =IF(B9-COUNTIF('Feed the Kraken'!M:M,"ไม่ทำ")=0,0,D9/(B9-COUNTIF('Feed the Kraken'!M:M,"ไม่ทำ")))
A10: Tic Tac Toe | B10: =COUNTA('Tic Tac Toe'!A:A)-1 | C10: =COUNTIF('Tic Tac Toe'!J:J,"สูง") | D10: =COUNTIF('Tic Tac Toe'!M:M,"เสร็จแล้ว") | E10: =COUNTIF('Tic Tac Toe'!M:M,"กำลังทำ") | F10: =COUNTIF('Tic Tac Toe'!M:M,"ยังไม่เริ่ม") | G10: =IF(B10-COUNTIF('Tic Tac Toe'!M:M,"ไม่ทำ")=0,0,D10/(B10-COUNTIF('Tic Tac Toe'!M:M,"ไม่ทำ")))
A11: รวม | B11: =SUM(B5:B10) | C11: =SUM(C5:C10) | D11: =SUM(D5:D10) | E11: =SUM(E5:E10) | F11: =SUM(F5:F10) | G11: =IF(B11=0,0,D11/B11)
A13: ข้อกำหนดทั่วไป
A14: • วางไฟล์ทั้งหมดในโฟลเดอร์ public/assets/ ตามคอลัมน์ 'ชื่อไฟล์ที่แนะนำ' (ในโค้ดเรียกเป็น /assets/...)
A15: • ทำรูปขนาด 2 เท่าของที่แสดงจริง (ขนาดในตารางคิดไว้แล้ว) เพื่อให้คมบนจอมือถือ
A16: • พยายามให้แต่ละไฟล์ไม่เกิน 200KB (พื้นหลังไม่เกิน 400KB) — ผู้เล่นทุกคนต้องโหลด
A17: • ไอคอน/ตัวหมากที่ต้องเปลี่ยนสีตามทีม ทำเป็น SVG สีเดียว (ขาว) แล้วให้โค้ดย้อมสี
A18: • การ์ดใช้อัตราส่วน 5:7 เว้นขอบ ~6% ไว้สำหรับมุมโค้ง และไม่ใส่ข้อความภาษาในรูป (ชื่อบทบาทโค้ดใส่ให้ทั้งไทย/อังกฤษ)
A19: • ฉากกองไฟต้องมี 2 สัดส่วน: กว้าง 16:10 (คอม) และสี่เหลี่ยม 1:1 (มือถือ) เว้นกลางภาพว่างไว้ให้วงผู้เล่น
A20: • สีประจำฝ่าย Kraken: แดง #c0392b (โจรสลัด/ตะวันตก), น้ำเงิน #2e86de (ลูกเรือ/ตะวันออก), เหลือง #d4a017 (ลัทธิ/เหนือ)
A21: • ใช้เฉพาะภาพที่วาดเองหรือมี license ให้ใช้ — ห้ามสแกนภาพจากกล่องเกมจริง
A22: • ความสำคัญ 'สูง' = เห็นตลอดเกม ทำก่อนแล้วจะเปลี่ยนบรรยากาศมากที่สุด

Sheet ทั่วไป
A1: ID | B1: หมวด | C1: ชื่อ asset | D1: ใช้ตรงไหน / รายละเอียด | E1: ชื่อไฟล์ที่แนะนำ (ใน public/) | F1: รูปแบบ | G1: ขนาด (px) | H1: พื้นใส | I1: เคลื่อนไหว | J1: ความสำคัญ | K1: ไฟล์โค้ดที่ต้องแก้ | L1: ตอนนี้เป็นอะไร | M1: สถานะ | N1: หมายเหตุ
A2: GEN-01 | B2: แบรนด์ | C2: โลโก้เว็บ | D2: หัวหน้าแรกและหัวห้อง | E2: public/assets/common/logo.svg | F2: SVG | G2: 512×160 | H2: ✓ | J2: สูง | K2: app/page.tsx, app/room/[code]/page.tsx | L2: ข้อความ + ไอคอน | M2: ยังไม่เริ่ม
A3: GEN-02 | B3: แบรนด์ | C3: Favicon / ไอคอนแอป | D3: แท็บเบราว์เซอร์ และไอคอนตอนเพิ่มลงหน้าจอมือถือ | E3: favicon.ico + assets/common/icon-512.png | F3: ICO + PNG | G3: 32 / 512 | H3: ✓ | J3: กลาง | K3: app/layout.tsx | L3: ไม่มี | M3: ยังไม่เริ่ม | N3: Next.js อ่าน app/icon.png ได้เองด้วย
A4: GEN-03 | B4: แบรนด์ | C4: ภาพแชร์ลิงก์ (OG image) | D4: พรีวิวตอนแชร์ลิงก์ห้องใน LINE/Discord | E4: public/assets/common/og.png | F4: PNG | G4: 1200×630 | J4: ต่ำ | K4: app/layout.tsx (metadata) | L4: ไม่มี | M4: ยังไม่เริ่ม
A5: GEN-04 | B5: หน้าแรก | C5: พื้นหลังหน้าแรก | D5: ฉากหลังหน้าเลือกเกม | E5: public/assets/common/home-bg.webp | F5: WebP | G5: 1920×1080 | J5: กลาง | K5: app/page.tsx | L5: สีพื้น night | M5: ยังไม่เริ่ม
A6: GEN-05 | B6: หน้าแรก | C6: ปกเกม Werewolf | D6: การ์ดเลือกเกมหน้าแรก และหน้า /games | E6: public/assets/covers/werewolf.webp | F6: WebP | G6: 1200×675 | J6: สูง | K6: app/page.tsx, app/games/page.tsx, lib/gamesCatalog.ts | L6: ไอคอน lucide | M6: ยังไม่เริ่ม
A7: GEN-06 | B7: หน้าแรก | C7: ปกเกม One Night | D7: เหมือนบน | E7: public/assets/covers/one-night.webp | F7: WebP | G7: 1200×675 | J7: สูง | K7: app/page.tsx, app/games/page.tsx, lib/gamesCatalog.ts | L7: ไอคอน lucide | M7: ยังไม่เริ่ม
A8: GEN-07 | B8: หน้าแรก | C8: ปกเกม Feed the Kraken | D8: เหมือนบน | E8: public/assets/covers/kraken.webp | F8: WebP | G8: 1200×675 | J8: สูง | K8: app/page.tsx, app/games/page.tsx, lib/gamesCatalog.ts | L8: ไอคอน lucide | M8: ยังไม่เริ่ม | N8: ห้ามใช้ภาพกล่องจริง
A9: GEN-08 | B9: หน้าแรก | C9: ปกเกม Tic Tac Toe | D9: เหมือนบน | E9: public/assets/covers/tictactoe.webp | F9: WebP | G9: 1200×675 | J9: กลาง | K9: app/page.tsx, app/games/page.tsx, lib/gamesCatalog.ts | L9: ไอคอน lucide | M9: ยังไม่เริ่ม
A10: GEN-09 | B10: ผู้เล่น | C10: รูปผู้เล่นเริ่มต้น (8 แบบ) | D10: รูปประจำตัวในวงกองไฟ/โต๊ะ สุ่มตามชื่อ (avatar-1 … avatar-8) | E10: public/assets/avatars/avatar-1.webp … avatar-8.webp | F10: WebP/PNG | G10: 256×256 | H10: ✓ | J10: สูง | K10: components/table/CampfireCircle.tsx, components/kraken/KrakenGame.tsx | L10: วงกลมสี + ตัวอักษรแรก | M10: ยังไม่เริ่ม | N10: นับเป็น 8 ไฟล์ ครอปวงกลมโดยโค้ด
A11: GEN-10 | B11: ผู้เล่น | C11: กรอบรูปผู้เล่น | D11: วงแหวนรอบรูป (ปกติ / ตัวเอง / ถูกเลือก) | E11: public/assets/common/portrait-frame.svg | F11: SVG | G11: 256×256 | H11: ✓ | J11: ต่ำ | K11: components/table/CampfireCircle.tsx | L11: เส้นขอบ CSS | M11: ยังไม่เริ่ม | N11: ทำเป็นสีขาวแล้วให้โค้ดย้อมสีได้
A12: GEN-11 | B12: ไอคอน | C12: มงกุฎหัวห้อง | D12: มุมรูปของหัวห้อง | E12: public/assets/icons/host.svg | F12: SVG | G12: 64×64 | H12: ✓ | J12: ต่ำ | K12: components/table/CampfireCircle.tsx | L12: ไอคอน Crown | M12: ยังไม่เริ่ม
A13: GEN-12 | B13: ไอคอน | C13: หลุดการเชื่อมต่อ | D13: มุมรูปคนที่หลุด | E13: public/assets/icons/offline.svg | F13: SVG | G13: 64×64 | H13: ✓ | J13: ต่ำ | K13: components/table/CampfireCircle.tsx | L13: ไอคอน WifiOff | M13: ยังไม่เริ่ม
A14: GEN-13 | B14: ไอคอน | C14: ตาย / ตกรอบ | D14: ทับบนรูปผู้เล่นที่ตาย | E14: public/assets/icons/dead.svg | F14: SVG | G14: 128×128 | H14: ✓ | J14: กลาง | K14: components/table/CampfireCircle.tsx | L14: ไอคอน Skull + ขาวดำ | M14: ยังไม่เริ่ม
A15: GEN-14 | B15: UI | C15: ปุ่ม | D15: ปุ่มหลักทุกหน้า (ถ้าอยากได้ลายไม้/กระดาษ) | E15: public/assets/ui/button.png | F15: PNG (9-slice) | G15: 96×48 | H15: ✓ | J15: ต่ำ | K15: components/ui/button.tsx | L15: CSS | M15: ยังไม่เริ่ม | N15: ใช้ border-image; ไม่จำเป็น
A16: GEN-15 | B16: UI | C16: พื้นการ์ด/แผง | D16: พื้นของกล่อง Card ทุกหน้า | E16: public/assets/ui/panel.png | F16: PNG (9-slice) | G16: 128×128 | H16: ✓ | J16: ต่ำ | K16: components/ui/card.tsx | L16: CSS | M16: ยังไม่เริ่ม | N16: ไม่จำเป็น
A17: GEN-16 | B17: เสียง | C17: เสียงแจ้งเตือนถึงตา | D17: เล่นเมื่อถึงตาเรา (ถ้าจะเพิ่มเสียง) | E17: public/assets/sfx/your-turn.mp3 | F17: MP3/OGG | G17: ≤ 2 วิ | J17: ต่ำ | K17: (ยังไม่มีระบบเสียง) | L17: ไม่มี | M17: ยังไม่เริ่ม | N17: ต้องเขียนระบบเสียงเพิ่ม

Sheet กองไฟ (Werewolf+ONW)
A1: ID | B1: หมวด | C1: ชื่อ asset | D1: ใช้ตรงไหน / รายละเอียด | E1: ชื่อไฟล์ที่แนะนำ (ใน public/) | F1: รูปแบบ | G1: ขนาด (px) | H1: พื้นใส | I1: เคลื่อนไหว | J1: ความสำคัญ | K1: ไฟล์โค้ดที่ต้องแก้ | L1: ตอนนี้เป็นอะไร | M1: สถานะ | N1: หมายเหตุ
A2: CAMP-01 | B2: ฉากกองไฟ | C2: ฉากกลางคืน (จอกว้าง) | D2: ป่า ท้องฟ้า ดาว พระจันทร์ ลานโล่งตรงกลาง — ใช้บนจอคอม/แท็บเล็ต (อัตราส่วน 16:10) | E2: public/assets/campfire/bg-night-wide.webp | F2: WebP | G2: 1920×1200 | J2: สูง | K2: components/table/CampfireCircle.tsx | L2: gradient + SVG ต้นไม้ | M2: ยังไม่เริ่ม | N2: เว้นกลางภาพไว้ให้กองไฟและวงผู้เล่น
A3: CAMP-02 | B3: ฉากกองไฟ | C3: ฉากกลางคืน (จอมือถือ) | D3: เหมือนบน แต่อัตราส่วน 1:1 | E3: public/assets/campfire/bg-night-square.webp | F3: WebP | G3: 1200×1200 | J3: สูง | K3: components/table/CampfireCircle.tsx | L3: gradient + SVG ต้นไม้ | M3: ยังไม่เริ่ม
A4: CAMP-03 | B4: ฉากกองไฟ | C4: ฉากกลางวัน/เย็น (จอกว้าง) | D4: ใช้ช่วงอภิปรายและโหวต | E4: public/assets/campfire/bg-day-wide.webp | F4: WebP | G4: 1920×1200 | J4: สูง | K4: components/table/CampfireCircle.tsx | L4: gradient + SVG ต้นไม้ | M4: ยังไม่เริ่ม
A5: CAMP-04 | B5: ฉากกองไฟ | C5: ฉากกลางวัน/เย็น (จอมือถือ) | D5: เหมือนบน อัตราส่วน 1:1 | E5: public/assets/campfire/bg-day-square.webp | F5: WebP | G5: 1200×1200 | J5: สูง | K5: components/table/CampfireCircle.tsx | L5: gradient + SVG ต้นไม้ | M5: ยังไม่เริ่ม
A6: CAMP-05 | B6: ฉากกองไฟ | C6: กองไฟ | D6: กลางวง มีเปลวไฟขยับ | E6: public/assets/campfire/fire-sprite.png | F6: PNG sprite / WebP เคลื่อนไหว | G6: 256×256 ต่อเฟรม | H6: ✓ | I6: ✓ | J6: สูง | K6: components/table/CampfireCircle.tsx | L6: SVG + animation CSS | M6: ยังไม่เริ่ม | N6: sprite แนวนอน 6–8 เฟรม หรือ Lottie
A7: CAMP-06 | B7: ฉากกองไฟ | C7: แสงไฟส่องพื้น | D7: วงแสงส้มรอบกองไฟ | E7: public/assets/campfire/firelight.png | F7: PNG | G7: 1024×1024 | H7: ✓ | J7: ต่ำ | K7: components/table/CampfireCircle.tsx | L7: radial-gradient | M7: ยังไม่เริ่ม | N7: โค้ดทำให้กระพริบเองได้
A8: CAMP-07 | B8: ฉากกองไฟ | C8: ตอไม้ที่นั่ง | D8: ใต้รูปผู้เล่นแต่ละคน | E8: public/assets/campfire/stump.png | F8: PNG | G8: 200×80 | H8: ✓ | J8: กลาง | K8: components/table/CampfireCircle.tsx | L8: วงรีสีน้ำตาล | M8: ยังไม่เริ่ม
A9: CAMP-08 | B9: ฉากกองไฟ | C9: ป้ายชื่อ | D9: พื้นป้ายชื่อใต้รูปผู้เล่น | E9: public/assets/campfire/nameplate.png | F9: PNG (9-slice) | G9: 160×40 | H9: ✓ | J9: ต่ำ | K9: components/table/CampfireCircle.tsx | L9: แถบดำโปร่ง | M9: ยังไม่เริ่ม
A10: CAMP-09 | B10: ฉากกองไฟ | C10: เครื่องหมายเลือกเป้าหมาย | D10: วงหรือเป้าที่ขึ้นเมื่อแตะเลือกคน | E10: public/assets/campfire/target.svg | F10: SVG | G10: 128×128 | H10: ✓ | J10: กลาง | K10: components/table/CampfireCircle.tsx | L10: ขอบแดง + ring | M10: ยังไม่เริ่ม
A11: CAMP-10 | B11: ฉากกองไฟ | C11: เหรียญ/ป้ายนับโหวต | D11: แสดงจำนวนโหวตใต้ชื่อ | E11: public/assets/campfire/vote-token.svg | F11: SVG | G11: 64×64 | H11: ✓ | J11: ต่ำ | K11: components/table/CampfireCircle.tsx | L11: ป้ายสีแดง | M11: ยังไม่เริ่ม

Sheet Werewolf
A1: ID | B1: หมวด | C1: ชื่อ asset | D1: ใช้ตรงไหน / รายละเอียด | E1: ชื่อไฟล์ที่แนะนำ (ใน public/) | F1: รูปแบบ | G1: ขนาด (px) | H1: พื้นใส | I1: เคลื่อนไหว | J1: ความสำคัญ | K1: ไฟล์โค้ดที่ต้องแก้ | L1: ตอนนี้เป็นอะไร | M1: สถานะ | N1: หมายเหตุ
A2: WW-01 | B2: การ์ดบทบาท | C2: หลังการ์ดบทบาท | D2: ตอนแจกบทบาทก่อนเปิด | E2: public/assets/werewolf/card-back.webp | F2: WebP | G2: 400×560 | J2: สูง | K2: components/game/RoleReveal.tsx | L2: CSS | M2: ยังไม่เริ่ม
A3: WW-02 | B3: การ์ดบทบาท | C3: การ์ด ชาวบ้าน (VILLAGER) | D3: หน้าเปิดบทบาท และป้ายบทบาทตัวเอง | E3: public/assets/werewolf/roles/villager.webp | F3: WebP | G3: 400×560 | J3: สูง | K3: components/game/RoleReveal.tsx, YourRoleBadge.tsx, roleMeta.ts | L3: ไอคอน User | M3: ยังไม่เริ่ม
A4: WW-03 | B4: การ์ดบทบาท | C4: การ์ด มนุษย์หมาป่า (WEREWOLF) | D4: เหมือนบน | E4: public/assets/werewolf/roles/werewolf.webp | F4: WebP | G4: 400×560 | J4: สูง | K4: components/game/RoleReveal.tsx, YourRoleBadge.tsx, roleMeta.ts | L4: ไอคอน Skull | M4: ยังไม่เริ่ม
A5: WW-04 | B5: การ์ดบทบาท | C5: การ์ด ผู้หยั่งรู้ (SEER) | D5: เหมือนบน | E5: public/assets/werewolf/roles/seer.webp | F5: WebP | G5: 400×560 | J5: สูง | K5: components/game/RoleReveal.tsx, YourRoleBadge.tsx, roleMeta.ts | L5: ไอคอน Eye | M5: ยังไม่เริ่ม
A6: WW-05 | B6: การ์ดบทบาท | C6: การ์ด หมอ (DOCTOR) | D6: เหมือนบน | E6: public/assets/werewolf/roles/doctor.webp | F6: WebP | G6: 400×560 | J6: สูง | K6: components/game/RoleReveal.tsx, YourRoleBadge.tsx, roleMeta.ts | L6: ไอคอน Shield | M6: ยังไม่เริ่ม
A7: WW-06 | B7: ไอคอนบทบาท | C7: ไอคอนบทบาท 4 แบบ | D7: ป้ายเล็กบนที่นั่ง แชท และหน้าจบเกม (villager / werewolf / seer / doctor) | E7: public/assets/werewolf/icons/<role>.svg | F7: SVG | G7: 128×128 | H7: ✓ | J7: กลาง | K7: components/game/roleMeta.ts | L7: ไอคอน lucide | M7: ยังไม่เริ่ม | N7: นับเป็น 4 ไฟล์
A8: WW-07 | B8: แอ็กชันกลางคืน | C8: ไอคอนกัด / ตรวจ / ปกป้อง | D8: หัวข้อคำสั่งตอนกลางคืนของหมาป่า ผู้หยั่งรู้ หมอ | E8: public/assets/werewolf/icons/act-kill.svg, act-see.svg, act-protect.svg | F8: SVG | G8: 96×96 | H8: ✓ | J8: ต่ำ | K8: components/game/NightPhase.tsx | L8: ไอคอน lucide | M8: ยังไม่เริ่ม | N8: ใช้ไอคอนบทบาทแทนได้
A9: WW-08 | B9: ผลตรวจ | C9: ตราผลผู้หยั่งรู้ | D9: ตราประทับ 'เป็นหมาป่า' / 'ไม่ใช่หมาป่า' | E9: public/assets/werewolf/seer-wolf.svg, seer-safe.svg | F9: SVG | G9: 256×256 | H9: ✓ | J9: กลาง | K9: components/game/SeerNote.tsx | L9: ข้อความสี | M9: ยังไม่เริ่ม
A10: WW-09 | B10: ประกาศ | C10: ประกาศเช้า: มีคนตาย / ไม่มีใครตาย | D10: ภาพตอนเริ่มกลางวัน | E10: public/assets/werewolf/dawn-death.webp, dawn-safe.webp | F10: WebP | G10: 1200×500 | J10: ต่ำ | K10: components/game/DayPhase.tsx | L10: ข้อความ | M10: ยังไม่เริ่ม
A11: WW-10 | B11: ประกาศ | C11: ภาพชาวบ้านชนะ | D11: หน้าจบเกม | E11: public/assets/werewolf/win-village.webp | F11: WebP | G11: 1600×600 | J11: กลาง | K11: components/game/GameOver.tsx | L11: ข้อความ + ไอคอน | M11: ยังไม่เริ่ม
A12: WW-11 | B12: ประกาศ | C12: ภาพหมาป่าชนะ | D12: หน้าจบเกม | E12: public/assets/werewolf/win-werewolf.webp | F12: WebP | G12: 1600×600 | J12: กลาง | K12: components/game/GameOver.tsx | L12: ข้อความ + ไอคอน | M12: ยังไม่เริ่ม
A13: WW-12 | B13: ไอคอน | C13: ไอคอนกลางคืน / กลางวัน / ค้อนโหวต / งดออกเสียง | D13: หัวข้อแต่ละช่วง | E13: public/assets/werewolf/icons/night.svg, day.svg, vote.svg, abstain.svg | F13: SVG | G13: 64×64 | H13: ✓ | J13: ต่ำ | K13: NightPhase.tsx, DayPhase.tsx, VotingPhase.tsx | L13: ไอคอน lucide | M13: ยังไม่เริ่ม

Sheet One Night
A1: ID | B1: หมวด | C1: ชื่อ asset | D1: ใช้ตรงไหน / รายละเอียด | E1: ชื่อไฟล์ที่แนะนำ (ใน public/) | F1: รูปแบบ | G1: ขนาด (px) | H1: พื้นใส | I1: เคลื่อนไหว | J1: ความสำคัญ | K1: ไฟล์โค้ดที่ต้องแก้ | L1: ตอนนี้เป็นอะไร | M1: สถานะ | N1: หมายเหตุ
A2: ONW-01 | B2: การ์ดบทบาท | C2: หลังการ์ด | D2: การ์ดกลาง 3 ใบข้างกองไฟ และการ์ดที่ยังไม่เปิด | E2: public/assets/onw/card-back.webp | F2: WebP | G2: 400×560 | J2: สูง | K2: components/onw/OnwPlayerList.tsx, YourRoleCard.tsx | L2: CSS | M2: ยังไม่เริ่ม
A3: ONW-02 | B3: การ์ดบทบาท | C3: การ์ด มนุษย์หมาป่า (WEREWOLF) | D3: การ์ดบทบาทตัวเอง การ์ดกลางที่แอบดู และหน้าจบเกม | E3: public/assets/onw/roles/werewolf.webp | F3: WebP | G3: 400×560 | J3: สูง | K3: components/onw/YourRoleCard.tsx, roleInfo.ts | L3: ไอคอน + สี | M3: ยังไม่เริ่ม
A4: ONW-03 | B4: การ์ดบทบาท | C4: การ์ด สมุน (MINION) | D4: การ์ดบทบาทตัวเอง การ์ดกลางที่แอบดู และหน้าจบเกม | E4: public/assets/onw/roles/minion.webp | F4: WebP | G4: 400×560 | J4: สูง | K4: components/onw/YourRoleCard.tsx, roleInfo.ts | L4: ไอคอน + สี | M4: ยังไม่เริ่ม
A5: ONW-04 | B5: การ์ดบทบาท | C5: การ์ด ช่างก่อสร้าง (MASON) | D5: การ์ดบทบาทตัวเอง การ์ดกลางที่แอบดู และหน้าจบเกม | E5: public/assets/onw/roles/mason.webp | F5: WebP | G5: 400×560 | J5: สูง | K5: components/onw/YourRoleCard.tsx, roleInfo.ts | L5: ไอคอน + สี | M5: ยังไม่เริ่ม
A6: ONW-05 | B6: การ์ดบทบาท | C6: การ์ด ผู้หยั่งรู้ (SEER) | D6: การ์ดบทบาทตัวเอง การ์ดกลางที่แอบดู และหน้าจบเกม | E6: public/assets/onw/roles/seer.webp | F6: WebP | G6: 400×560 | J6: สูง | K6: components/onw/YourRoleCard.tsx, roleInfo.ts | L6: ไอคอน + สี | M6: ยังไม่เริ่ม
A7: ONW-06 | B7: การ์ดบทบาท | C7: การ์ด โจร (ROBBER) | D7: การ์ดบทบาทตัวเอง การ์ดกลางที่แอบดู และหน้าจบเกม | E7: public/assets/onw/roles/robber.webp | F7: WebP | G7: 400×560 | J7: สูง | K7: components/onw/YourRoleCard.tsx, roleInfo.ts | L7: ไอคอน + สี | M7: ยังไม่เริ่ม
A8: ONW-07 | B8: การ์ดบทบาท | C8: การ์ด ตัวป่วน (TROUBLEMAKER) | D8: การ์ดบทบาทตัวเอง การ์ดกลางที่แอบดู และหน้าจบเกม | E8: public/assets/onw/roles/troublemaker.webp | F8: WebP | G8: 400×560 | J8: สูง | K8: components/onw/YourRoleCard.tsx, roleInfo.ts | L8: ไอคอน + สี | M8: ยังไม่เริ่ม
A9: ONW-08 | B9: การ์ดบทบาท | C9: การ์ด ขี้เมา (DRUNK) | D9: การ์ดบทบาทตัวเอง การ์ดกลางที่แอบดู และหน้าจบเกม | E9: public/assets/onw/roles/drunk.webp | F9: WebP | G9: 400×560 | J9: สูง | K9: components/onw/YourRoleCard.tsx, roleInfo.ts | L9: ไอคอน + สี | M9: ยังไม่เริ่ม
A10: ONW-09 | B10: การ์ดบทบาท | C10: การ์ด คนนอนไม่หลับ (INSOMNIAC) | D10: การ์ดบทบาทตัวเอง การ์ดกลางที่แอบดู และหน้าจบเกม | E10: public/assets/onw/roles/insomniac.webp | F10: WebP | G10: 400×560 | J10: สูง | K10: components/onw/YourRoleCard.tsx, roleInfo.ts | L10: ไอคอน + สี | M10: ยังไม่เริ่ม
A11: ONW-10 | B11: การ์ดบทบาท | C11: การ์ด ช่างฟอกหนัง (TANNER) | D11: การ์ดบทบาทตัวเอง การ์ดกลางที่แอบดู และหน้าจบเกม | E11: public/assets/onw/roles/tanner.webp | F11: WebP | G11: 400×560 | J11: สูง | K11: components/onw/YourRoleCard.tsx, roleInfo.ts | L11: ไอคอน + สี | M11: ยังไม่เริ่ม
A12: ONW-11 | B12: การ์ดบทบาท | C12: การ์ด นายพราน (HUNTER) | D12: การ์ดบทบาทตัวเอง การ์ดกลางที่แอบดู และหน้าจบเกม | E12: public/assets/onw/roles/hunter.webp | F12: WebP | G12: 400×560 | J12: สูง | K12: components/onw/YourRoleCard.tsx, roleInfo.ts | L12: ไอคอน + สี | M12: ยังไม่เริ่ม
A13: ONW-12 | B13: การ์ดบทบาท | C13: การ์ด ชาวบ้าน (VILLAGER) | D13: การ์ดบทบาทตัวเอง การ์ดกลางที่แอบดู และหน้าจบเกม | E13: public/assets/onw/roles/villager.webp | F13: WebP | G13: 400×560 | J13: สูง | K13: components/onw/YourRoleCard.tsx, roleInfo.ts | L13: ไอคอน + สี | M13: ยังไม่เริ่ม
A14: ONW-13 | B14: ไอคอนบทบาท | C14: ไอคอนบทบาท 11 แบบ | D14: ป้ายเล็กใน log กลางคืน และบนที่นั่งตอนจบเกม | E14: public/assets/onw/icons/<role>.svg | F14: SVG | G14: 128×128 | H14: ✓ | J14: กลาง | K14: components/onw/roleInfo.ts, NightLog.tsx | L14: ไอคอน lucide | M14: ยังไม่เริ่ม | N14: นับเป็น 11 ไฟล์
A15: ONW-14 | B15: การ์ดกลาง | C15: ช่องวางการ์ดกลาง | D15: ที่วางการ์ด 3 ใบข้างกองไฟ | E15: public/assets/onw/center-slot.png | F15: PNG | G15: 200×280 | H15: ✓ | J15: ต่ำ | K15: components/onw/OnwPlayerList.tsx | L15: ขอบ CSS | M15: ยังไม่เริ่ม
A16: ONW-15 | B16: แอ็กชัน | C16: ไอคอนสลับการ์ด | D16: แสดงใน log ของโจร ตัวป่วน ขี้เมา | E16: public/assets/onw/icons/swap.svg | F16: SVG | G16: 96×96 | H16: ✓ | J16: ต่ำ | K16: components/onw/NightLog.tsx | L16: ข้อความ | M16: ยังไม่เริ่ม
A17: ONW-16 | B17: แอ็กชัน | C17: ไอคอนแอบดู | D17: แสดงใน log ของผู้หยั่งรู้ หมาป่าตัวเดียว คนนอนไม่หลับ | E17: public/assets/onw/icons/peek.svg | F17: SVG | G17: 96×96 | H17: ✓ | J17: ต่ำ | K17: components/onw/NightLog.tsx | L17: ข้อความ | M17: ยังไม่เริ่ม
A18: ONW-17 | B18: ประกาศ | C18: ภาพหมู่บ้านชนะ | D18: หน้าจบเกม | E18: public/assets/onw/win-village.webp | F18: WebP | G18: 1600×600 | J18: กลาง | K18: components/onw/OnwGameOver.tsx | L18: ข้อความ | M18: ยังไม่เริ่ม
A19: ONW-18 | B19: ประกาศ | C19: ภาพหมาป่าชนะ | D19: หน้าจบเกม | E19: public/assets/onw/win-werewolf.webp | F19: WebP | G19: 1600×600 | J19: กลาง | K19: components/onw/OnwGameOver.tsx | L19: ข้อความ | M19: ยังไม่เริ่ม
A20: ONW-19 | B20: ประกาศ | C20: ภาพช่างฟอกหนังชนะ | D20: หน้าจบเกม | E20: public/assets/onw/win-tanner.webp | F20: WebP | G20: 1600×600 | J20: กลาง | K20: components/onw/OnwGameOver.tsx | L20: ข้อความ | M20: ยังไม่เริ่ม

Sheet Feed the Kraken
A1: ID | B1: หมวด | C1: ชื่อ asset | D1: ใช้ตรงไหน / รายละเอียด | E1: ชื่อไฟล์ที่แนะนำ (ใน public/) | F1: รูปแบบ | G1: ขนาด (px) | H1: พื้นใส | I1: เคลื่อนไหว | J1: ความสำคัญ | K1: ไฟล์โค้ดที่ต้องแก้ | L1: ตอนนี้เป็นอะไร | M1: สถานะ | N1: หมายเหตุ
A2: KR-01 | B2: กระดาน | C2: ทะเล (พื้นแผนที่) | D2: พื้นหลังแผนที่ใต้ช่องหกเหลี่ยม | E2: public/assets/kraken/board/sea.webp | F2: WebP | G2: 1600×1100 | J2: สูง | K2: components/kraken/KrakenBoard.tsx | L2: สีน้ำเงิน SVG | M2: ยังไม่เริ่ม | N2: หรือทำเป็นลายวนซ้ำ 512×512
A3: KR-02 | B3: กระดาน | C3: ช่องหกเหลี่ยม: ทะเลปกติ | D3: ช่องที่เรือแล่นได้ | E3: public/assets/kraken/board/hex-sea.svg | F3: SVG | G3: 104×120 | H3: ✓ | J3: สูง | K3: components/kraken/KrakenBoard.tsx | L3: polygon SVG | M3: ยังไม่เริ่ม | N3: หกเหลี่ยมยอดแหลมขึ้นบน-ลง (pointy-top) กว้าง:สูง = √3:2
A4: KR-03 | B4: กระดาน | C4: ช่องหกเหลี่ยม: เขตแดง (โจรสลัด) | D4: ฝั่งตะวันตก | E4: public/assets/kraken/board/hex-red.svg | F4: SVG | G4: 104×120 | H4: ✓ | J4: กลาง | K4: components/kraken/KrakenBoard.tsx | L4: polygon สีแดง | M4: ยังไม่เริ่ม
A5: KR-04 | B5: กระดาน | C5: ช่องหกเหลี่ยม: เขตน้ำเงิน (ลูกเรือ) | D5: ฝั่งตะวันออก | E5: public/assets/kraken/board/hex-blue.svg | F5: SVG | G5: 104×120 | H5: ✓ | J5: กลาง | K5: components/kraken/KrakenBoard.tsx | L5: polygon สีน้ำเงิน | M5: ยังไม่เริ่ม
A6: KR-05 | B6: กระดาน | C6: ช่องหกเหลี่ยม: เขตเหลือง (คราเคน) | D6: ฝั่งเหนือ | E6: public/assets/kraken/board/hex-yellow.svg | F6: SVG | G6: 104×120 | H6: ✓ | J6: กลาง | K6: components/kraken/KrakenBoard.tsx | L6: polygon สีเหลือง | M6: ยังไม่เริ่ม
A7: KR-06 | B7: กระดาน | C7: อ่าวโจรสลัด | D7: จุดหมายฝั่งแดง | E7: public/assets/kraken/board/dest-pirate-cove.png | F7: PNG | G7: 320×320 | H7: ✓ | J7: สูง | K7: components/kraken/KrakenBoard.tsx | L7: ไอคอน + ข้อความ | M7: ยังไม่เริ่ม
A8: KR-07 | B8: กระดาน | C8: อ่าวลูกเรือ | D8: จุดหมายฝั่งน้ำเงิน | E8: public/assets/kraken/board/dest-sailor-bay.png | F8: PNG | G8: 320×320 | H8: ✓ | J8: สูง | K8: components/kraken/KrakenBoard.tsx | L8: ไอคอน + ข้อความ | M8: ยังไม่เริ่ม
A9: KR-08 | B9: กระดาน | C9: คราเคน | D9: จุดหมายฝั่งเหลือง | E9: public/assets/kraken/board/dest-kraken.png | F9: PNG | G9: 400×400 | H9: ✓ | J9: สูง | K9: components/kraken/KrakenBoard.tsx | L9: ไอคอน + ข้อความ | M9: ยังไม่เริ่ม
A10: KR-09 | B10: กระดาน | C10: เรือ | D10: ตัวเรือที่เลื่อนบนแผนที่ (มองจากบน) | E10: public/assets/kraken/board/ship.png | F10: PNG/SVG | G10: 160×160 | H10: ✓ | J10: สูง | K10: components/kraken/KrakenBoard.tsx | L10: SVG เรือ | M10: ยังไม่เริ่ม | N10: ถ้าทำหลายมุมหันได้ ให้หัวเรือชี้ขึ้น
A11: KR-10 | B11: กระดาน | C11: เส้นเสบียง | D11: แถวเติมปืน (แผนที่ยาว) | E11: public/assets/kraken/board/supply-line.svg | F11: SVG | G11: ยืดได้ | H11: ✓ | J11: ต่ำ | K11: components/kraken/KrakenBoard.tsx | L11: เส้นประ | M11: ยังไม่เริ่ม
A12: KR-11 | B12: กระดาน | C12: ตัวนับรอบ | D12: มุมแผนที่ | E12: public/assets/kraken/board/round-counter.svg | F12: SVG | G12: 128×128 | H12: ✓ | J12: ต่ำ | K12: components/kraken/KrakenBoard.tsx | L12: ข้อความ | M12: ยังไม่เริ่ม
A13: KR-12 | B13: ช่องพิเศษ | C13: ค้นห้อง (CABIN_SEARCH) | D13: ไอคอนบนช่องหกเหลี่ยม + ในหน้าคำสั่ง | E13: public/assets/kraken/actions/cabin-search.svg | F13: SVG | G13: 96×96 | H13: ✓ | J13: สูง | K13: components/kraken/krakenMeta.ts | L13: ไอคอน Search | M13: ยังไม่เริ่ม
A14: KR-13 | B14: ช่องพิเศษ | C14: เฆี่ยน (FLOGGING) | D14: เหมือนบน | E14: public/assets/kraken/actions/flogging.svg | F14: SVG | G14: 96×96 | H14: ✓ | J14: สูง | K14: components/kraken/krakenMeta.ts | L14: ไอคอน Gavel | M14: ยังไม่เริ่ม
A15: KR-14 | B15: ช่องพิเศษ | C15: ตัดลิ้น (OFF_WITH_TONGUE) | D15: เหมือนบน | E15: public/assets/kraken/actions/off-with-tongue.svg | F15: SVG | G15: 96×96 | H15: ✓ | J15: สูง | K15: components/kraken/krakenMeta.ts | L15: ไอคอน MicOff | M15: ยังไม่เริ่ม
A16: KR-15 | B16: ช่องพิเศษ | C16: โยนให้คราเคน (FEED_THE_KRAKEN) | D16: เหมือนบน | E16: public/assets/kraken/actions/feed-the-kraken.svg | F16: SVG | G16: 96×96 | H16: ✓ | J16: สูง | K16: components/kraken/krakenMeta.ts | L16: ไอคอน Droplets | M16: ยังไม่เริ่ม
A17: KR-16 | B17: โต๊ะ | C17: ลายไม้โต๊ะ | D17: พื้นโต๊ะรอบกระดาน | E17: public/assets/kraken/table/wood.webp | F17: WebP (ลายวนซ้ำ) | G17: 1024×1024 | J17: สูง | K17: components/kraken/KrakenGame.tsx | L17: gradient น้ำตาล | M17: ยังไม่เริ่ม | N17: ต้อง seamless ต่อขอบได้
A18: KR-17 | B18: โต๊ะ | C18: ที่นั่งผู้เล่น | D18: พื้นป้ายของแต่ละที่นั่ง | E18: public/assets/kraken/table/seat.png | F18: PNG (9-slice) | G18: 240×140 | H18: ✓ | J18: กลาง | K18: components/kraken/KrakenGame.tsx | L18: กล่อง CSS | M18: ยังไม่เริ่ม
A19: KR-18 | B19: ตำแหน่ง | C19: ป้ายตั้ง กัปตัน | D19: ตั้งหน้าที่นั่งกัปตัน | E19: public/assets/kraken/standees/captain.png | F19: PNG | G19: 256×256 | H19: ✓ | J19: สูง | K19: components/kraken/KrakenGame.tsx | L19: ไอคอน Crown | M19: ยังไม่เริ่ม
A20: KR-19 | B20: ตำแหน่ง | C20: ป้ายตั้ง ต้นหนเรือรอง (Lieutenant) | D20: เหมือนบน | E20: public/assets/kraken/standees/lieutenant.png | F20: PNG | G20: 256×256 | H20: ✓ | J20: สูง | K20: components/kraken/KrakenGame.tsx | L20: ไอคอน Star | M20: ยังไม่เริ่ม
A21: KR-20 | B21: ตำแหน่ง | C21: ป้ายตั้ง ต้นหน (Navigator) | D21: เหมือนบน | E21: public/assets/kraken/standees/navigator.png | F21: PNG | G21: 256×256 | H21: ✓ | J21: สูง | K21: components/kraken/KrakenGame.tsx | L21: ไอคอน Compass | M21: ยังไม่เริ่ม
A22: KR-21 | B22: ตำแหน่ง | C22: ป้ายพักเวร (Off-duty) | D22: วางบนที่นั่งคนที่พักเวร | E22: public/assets/kraken/tokens/off-duty.png | F22: PNG | G22: 128×128 | H22: ✓ | J22: กลาง | K22: components/kraken/KrakenGame.tsx | L22: ไอคอน Moon | M22: ยังไม่เริ่ม
A23: KR-22 | B23: โทเคน | C23: ปืน | D23: นับปืนบนที่นั่ง และปุ่มชูปืนตอนกบฏ | E23: public/assets/kraken/tokens/gun.png | F23: PNG/SVG | G23: 128×128 | H23: ✓ | J23: สูง | K23: components/kraken/KrakenGame.tsx, components/kraken/krakenMeta.ts | L23: ไอคอน Crosshair | M23: ยังไม่เริ่ม
A24: KR-23 | B24: โทเคน | C24: ใบสมัคร (Résumé) | D24: นับจำนวนครั้งที่เคยเป็นเจ้าหน้าที่ | E24: public/assets/kraken/tokens/resume.png | F24: PNG | G24: 128×128 | H24: ✓ | J24: กลาง | K24: components/kraken/KrakenGame.tsx | L24: ไอคอน | M24: ยังไม่เริ่ม
A25: KR-24 | B25: โทเคน | C25: ป้าย 'ไม่ใช่ฝ่าย X' (จากการเฆี่ยน) | D25: ชิปบนที่นั่ง 3 สี | E25: public/assets/kraken/tokens/not-red.svg, not-blue.svg, not-yellow.svg | F25: SVG | G25: 96×96 | H25: ✓ | J25: ต่ำ | K25: components/kraken/KrakenGame.tsx | L25: ชิปสี | M25: ยังไม่เริ่ม | N25: นับเป็น 3 ไฟล์
A26: KR-25 | B26: โทเคน | C26: ถูกตัดลิ้น | D26: บนที่นั่งคนที่พูดไม่ได้ | E26: public/assets/kraken/tokens/tongueless.svg | F26: SVG | G26: 96×96 | H26: ✓ | J26: ต่ำ | K26: components/kraken/KrakenGame.tsx | L26: ไอคอน MicOff | M26: ยังไม่เริ่ม
A27: KR-26 | B27: โทเคน | C27: ถูกโยนให้คราเคน | D27: บนที่นั่งคนที่ตกรอบ | E27: public/assets/kraken/tokens/fed.svg | F27: SVG | G27: 128×128 | H27: ✓ | J27: ต่ำ | K27: components/kraken/KrakenGame.tsx | L27: ไอคอน Skull | M27: ยังไม่เริ่ม
A28: KR-27 | B28: การ์ดบทบาท | C28: หลังการ์ดบทบาท | D28: การ์ดบทบาทก่อนเปิด | E28: public/assets/kraken/roles/back.webp | F28: WebP | G28: 400×560 | J28: สูง | K28: components/kraken/KrakenGame.tsx | L28: CSS | M28: ยังไม่เริ่ม
A29: KR-28 | B29: การ์ดบทบาท | C29: ลูกเรือ (SAILOR) | D29: การ์ดบทบาทตัวเอง และหน้าจบเกม | E29: public/assets/kraken/roles/sailor.webp | F29: WebP | G29: 400×560 | J29: สูง | K29: components/kraken/KrakenGame.tsx, components/kraken/krakenMeta.ts | L29: ไอคอน Anchor | M29: ยังไม่เริ่ม
A30: KR-29 | B30: การ์ดบทบาท | C30: โจรสลัด (PIRATE) | D30: เหมือนบน | E30: public/assets/kraken/roles/pirate.webp | F30: WebP | G30: 400×560 | J30: สูง | K30: components/kraken/KrakenGame.tsx, components/kraken/krakenMeta.ts | L30: ไอคอน Skull | M30: ยังไม่เริ่ม
A31: KR-30 | B31: การ์ดบทบาท | C31: ผู้นำลัทธิ (CULT_LEADER) | D31: เหมือนบน | E31: public/assets/kraken/roles/cult-leader.webp | F31: WebP | G31: 400×560 | J31: สูง | K31: components/kraken/KrakenGame.tsx, components/kraken/krakenMeta.ts | L31: ไอคอน Waves | M31: ยังไม่เริ่ม
A32: KR-31 | B32: การ์ดบทบาท | C32: สาวกลัทธิ (CULTIST) | D32: เหมือนบน (ได้จากพิธีชักชวน) | E32: public/assets/kraken/roles/cultist.webp | F32: WebP | G32: 400×560 | J32: สูง | K32: components/kraken/KrakenGame.tsx, components/kraken/krakenMeta.ts | L32: ไอคอน Waves | M32: ยังไม่เริ่ม
A33: KR-32 | B33: การ์ดนำทาง | C33: หลังการ์ดนำทาง | D33: กองจั่ว และการ์ดในมือคนอื่น | E33: public/assets/kraken/nav/back.webp | F33: WebP | G33: 300×420 | J33: สูง | K33: components/kraken/KrakenGame.tsx | L33: CSS | M33: ยังไม่เริ่ม
A34: KR-33 | B34: การ์ดนำทาง | C34: แดง – เมา | D34: ผลักไปตะวันตก + กัปตันเมา (มี 5 ใบในสำรับยาว) | E34: public/assets/kraken/nav/red-drunk.webp | F34: WebP | G34: 300×420 | J34: สูง | K34: components/kraken/KrakenGame.tsx | L34: กรอบสี + ไอคอน Wine | M34: ยังไม่เริ่ม
A35: KR-34 | B35: การ์ดนำทาง | C35: แดง – นางเงือก | D35: ผลักไปตะวันตก + นางเงือก | E35: public/assets/kraken/nav/red-mermaid.webp | F35: WebP | G35: 300×420 | J35: สูง | K35: components/kraken/KrakenGame.tsx | L35: กรอบสี + ไอคอน Fish | M35: ยังไม่เริ่ม
A36: KR-35 | B36: การ์ดนำทาง | C36: แดง – กล้องส่องทางไกล | D36: ผลักไปตะวันตก + กล้องส่องทางไกล | E36: public/assets/kraken/nav/red-telescope.webp | F36: WebP | G36: 300×420 | J36: สูง | K36: components/kraken/KrakenGame.tsx | L36: กรอบสี + ไอคอน Telescope | M36: ยังไม่เริ่ม
A37: KR-36 | B37: การ์ดนำทาง | C37: แดง – ติดอาวุธ | D37: ผลักไปตะวันตก + ได้ปืน | E37: public/assets/kraken/nav/red-armed.webp | F37: WebP | G37: 300×420 | J37: สูง | K37: components/kraken/KrakenGame.tsx | L37: กรอบสี + ไอคอน Crosshair | M37: ยังไม่เริ่ม
A38: KR-37 | B38: การ์ดนำทาง | C38: น้ำเงิน – เมา | D38: ผลักไปตะวันออก + กัปตันเมา | E38: public/assets/kraken/nav/blue-drunk.webp | F38: WebP | G38: 300×420 | J38: สูง | K38: components/kraken/KrakenGame.tsx | L38: กรอบสี + ไอคอน Wine | M38: ยังไม่เริ่ม
A39: KR-38 | B39: การ์ดนำทาง | C39: น้ำเงิน – ปลดอาวุธ | D39: ผลักไปตะวันออก + เสียปืน | E39: public/assets/kraken/nav/blue-disarmed.webp | F39: WebP | G39: 300×420 | J39: สูง | K39: components/kraken/KrakenGame.tsx | L39: กรอบสี + ไอคอน ShieldOff | M39: ยังไม่เริ่ม
A40: KR-39 | B40: การ์ดนำทาง | C40: เหลือง – ลัทธิลุกฮือ | D40: ผลักไปเหนือ + ผู้นำลัทธิทำพิธี | E40: public/assets/kraken/nav/yellow-cult-uprising.webp | F40: WebP | G40: 300×420 | J40: สูง | K40: components/kraken/KrakenGame.tsx | L40: กรอบสี + ไอคอน Flame | M40: ยังไม่เริ่ม
...

Sheet Tic Tac Toe
A1: ID | B1: หมวด | C1: ชื่อ asset | D1: ใช้ตรงไหน / รายละเอียด | E1: ชื่อไฟล์ที่แนะนำ (ใน public/) | F1: รูปแบบ | G1: ขนาด (px) | H1: พื้นใส | I1: เคลื่อนไหว | J1: ความสำคัญ | K1: ไฟล์โค้ดที่ต้องแก้ | L1: ตอนนี้เป็นอะไร | M1: สถานะ | N1: หมายเหตุ
A2: TTT-01 | B2: กระดาน | C2: กระดานไม้ | D2: พื้นกระดาน 3×3 พร้อมร่องแบ่งช่อง | E2: public/assets/tictactoe/board.webp | F2: WebP | G2: 1200×1200 | J2: สูง | K2: components/tictactoe/TicTacToeRoom.tsx | L2: CSS ลายไม้ | M2: ยังไม่เริ่ม | N2: ร่องควรตรงตำแหน่ง 1/3 และ 2/3 พอดี
A3: TTT-02 | B3: ตัวหมาก | C3: ตัว X (ไม้วอลนัท) | D3: หมากผู้เล่น X | E3: public/assets/tictactoe/x.png | F3: PNG | G3: 320×320 | H3: ✓ | J3: สูง | K3: components/tictactoe/TicTacToeRoom.tsx | L3: แท่ง CSS 2 อันไขว้ | M3: ยังไม่เริ่ม
A4: TTT-03 | B4: ตัวหมาก | C4: ตัว O (ไม้เมเปิล) | D4: หมากผู้เล่น O | E4: public/assets/tictactoe/o.png | F4: PNG | G4: 320×320 | H4: ✓ | J4: สูง | K4: components/tictactoe/TicTacToeRoom.tsx | L4: วงแหวน CSS | M4: ยังไม่เริ่ม
A5: TTT-04 | B5: ตัวหมาก | C5: เงาหมากตอนชี้ | D5: ตัวจางตอนเอาเมาส์ชี้ช่องว่าง | E5: public/assets/tictactoe/x-ghost.png, o-ghost.png | F5: PNG | G5: 320×320 | H5: ✓ | J5: ต่ำ | K5: components/tictactoe/TicTacToeRoom.tsx | L5: ไม่มี | M5: ยังไม่เริ่ม | N5: ทำ opacity ด้วยโค้ดแทนได้
A6: TTT-05 | B6: เอฟเฟกต์ | C6: แสงแถวที่ชนะ | D6: ขีด/แสงพาดผ่าน 3 ช่องที่ชนะ | E6: public/assets/tictactoe/win-line.png | F6: PNG | G6: 1200×80 | H6: ✓ | J6: กลาง | K6: components/tictactoe/TicTacToeRoom.tsx | L6: เงาเรืองสีอำพัน | M6: ยังไม่เริ่ม
A7: TTT-06 | B7: โต๊ะ | C7: พื้นโต๊ะรอบกระดาน | D7: ฉากหลังรอบกระดาน | E7: public/assets/tictactoe/table.webp | F7: WebP | G7: 1920×1080 | J7: ต่ำ | K7: components/tictactoe/TicTacToeRoom.tsx | L7: สีพื้น | M7: ยังไม่เริ่ม
A8: TTT-07 | B8: ประกาศ | C8: ภาพชนะ / เสมอ | D8: ข้อความจบเกม | E8: public/assets/tictactoe/win.webp, draw.webp | F8: WebP | G8: 800×300 | H8: ✓ | J8: ต่ำ | K8: components/tictactoe/TicTacToeRoom.tsx | L8: ข้อความ | M8: ยังไม่เริ่ม
